<?xml version="1.0" ?>
<robot name="Vector">
    <link name='body'>
      <!--<pose frame=''>-0.015 0 0.01 0 -0 0</pose>-->
      <!--<origin xyz="-0.015 0 0.01" rpy="0 -0 0" />-->
      <inertial>
        <mass value="0.8"/>
        <inertia ixx="0.001" ixy="0.0" ixz="0.0" iyy="0.001" iyz="0.0" izz="0.001"/>
        <pose frame=''>0 0 0 0 -0 0</pose>
        <!--<origin xyz="0 0 0" rpy="0 -0 0" />-->
      </inertial>
      <self_collide>0</self_collide>
      <enable_wind>0</enable_wind>
      <kinematic>0</kinematic>
      <gravity>1</gravity>
      <visual name='visual'>
        <geometry>
          <mesh filename="body.obj" scale="0.01 0.01 0.01"/>
        </geometry>
        <!--<pose frame=''>0.015 0 -0.005 0 -0 0</pose>-->
        <!--<origin xyz="0.015 0 -0.005" rpy="0 -0 0" />-->
        <!--<transparency>0</transparency>
        <cast_shadows>1</cast_shadows>-->
      </visual>
      <collision name='collision'>
        <laser_retro>0</laser_retro>
        <max_contacts>10</max_contacts>
        <!--<pose frame=''>-0.01 0 0.03 0 -0 0</pose>-->
        <origin xyz="-0.01 0 0.05" rpy="0 -0 0" />
        <geometry>
          <box size="0.065 0.045 0.07"/>
        </geometry>
      </collision>
    </link>
    <link name='anki_vector::anki_vector::robot::forklift'>
      <inertial>
        <mass value="0.0001"/>
        <inertia ixx="0.001" ixy="0.0" ixz="0.0" iyy="0.001" iyz="0.0" izz="0.001"/>
        <pose frame=''>-0.1 0 0.1 0 -0 0</pose>
        <!--<origin xyz="-0.1 0 0.1" rpy="0 -0 0" />-->
      </inertial>
      <self_collide>0</self_collide>
      <enable_wind>0</enable_wind>
      <kinematic>0</kinematic>
      <gravity>1</gravity>
      <pose frame=''>0 0 0 0 -0 0</pose>
      <!--<origin xyz="0 0 0" rpy="0 -0 0" />-->
      <visual name='visual'>
        <geometry>
          <mesh filename="forklift.obj" scale="0.01 0.01 0.01"/>
        </geometry>
        <pose frame=''>0 0 0.001 0 -0 0</pose>
        <!--<origin xyz="0 0 0.001" rpy="0 -0 0" />-->
        <transparency>0.5</transparency>
        <cast_shadows>1</cast_shadows>
        <!--<material>
          <shader type='pixel'/>
        </material>-->
      </visual>
      <!--<collision name='collision'>
        <laser_retro>0</laser_retro>
        <max_contacts>10</max_contacts>
        <pose frame=''>-0.019 0 0 0 -0 0</pose>
        <origin xyz="-0.019 0 0" rpy="0 -0 0" />
        <geometry>
          <box size="0.072 0.055 0.1"/>
        </geometry>
      </collision>-->
    </link>
    <link name='anki_vector::anki_vector::robot::head'>
      <!--<pose frame=''>-0.02 -0 0.048 0 -0 0</pose>-->
      <!--<origin xyz="-0.02 -0 0.048" rpy="0 -0 0" />-->
      <inertial>
        <mass value="0.8"/>
        <inertia ixx="0.001" ixy="0.0" ixz="0.0" iyy="0.001" iyz="0.0" izz="0.001"/>
        <pose frame=''>0 0 0 0 -0 0</pose>
        <origin xyz="0 0 0" rpy="0 -0 0" />
      </inertial>
      <self_collide>0</self_collide>
      <enable_wind>0</enable_wind>
      <kinematic>0</kinematic>
      <!--<gravity>1</gravity>-->
      <visual name='visual'>
        <geometry>
          <mesh filename="head.obj" scale="0.01 0.01 0.01"/>
        </geometry>
        <pose frame=''>0.02 0 -0.04 0 -0 0</pose>
        <!--<origin xyz="0.02 0 -0.04" rpy="0 -0 0" />-->
        <!--<material name="blue"><color rgba="0 0 .8 1"/></material>-->
      </visual>
      <collision name='collision'>
        <laser_retro>0</laser_retro>
        <max_contacts>10</max_contacts>
        <pose frame=''>0 0 0 0 -0 0</pose>
        <origin xyz="0 0 0.1" rpy="0 -0 0" />
        <geometry>
          <box size="0.04 0.04 0.04"/>
        </geometry>
        <surface>
          <friction>
            <ode>
              <mu>1</mu>
              <mu2>1</mu2>
              <fdir1>0 0 0</fdir1>
              <slip1>0</slip1>
              <slip2>0</slip2>
            </ode>
            <torsional>
              <coefficient>1</coefficient>
              <patch_radius>0</patch_radius>
              <surface_radius>0</surface_radius>
              <use_patch_radius>1</use_patch_radius>
              <ode>
                <slip>0</slip>
              </ode>
            </torsional>
          </friction>
          <bounce>
            <restitution_coefficient>0</restitution_coefficient>
            <threshold>1e+06</threshold>
          </bounce>
          <contact>
            <collide_without_contact>0</collide_without_contact>
            <collide_without_contact_bitmask>1</collide_without_contact_bitmask>
            <collide_bitmask>1</collide_bitmask>
            <ode>
              <soft_cfm>0</soft_cfm>
              <soft_erp>0.2</soft_erp>
              <kp>1e+13</kp>
              <kd>1</kd>
              <max_vel>0.01</max_vel>
              <min_depth>0</min_depth>
            </ode>
            <bullet>
              <split_impulse>1</split_impulse>
              <split_impulse_penetration_threshold>-0.01</split_impulse_penetration_threshold>
              <soft_cfm>0</soft_cfm>
              <soft_erp>0.2</soft_erp>
              <kp>1e+13</kp>
              <kd>1</kd>
            </bullet>
          </contact>
        </surface>
      </collision>
    </link>
    <link name='anki_vector::anki_vector::robot::tracks'>
      <inertial>
        <mass value="0.0001"/>
        <inertia ixx="0.001" ixy="0.0" ixz="0.0" iyy="0.001" iyz="0.0" izz="0.001"/>
        <pose frame=''>-0.1 0 0.1 0 -0 0</pose>
        <!--<origin xyz="-0.1 0 0.1" rpy="0 -0 0" />-->
      </inertial>
      <self_collide>0</self_collide>
      <enable_wind>0</enable_wind>
      <kinematic>0</kinematic>
      <gravity>1</gravity>
      <pose frame=''>0 0 0 0 -0 0</pose>
      <!--<origin xyz="0 0 0" rpy="0 -0 0" />-->
      <visual name='visual'>
        <geometry>
          <mesh filename="tracks.obj" scale="0.01 0.01 0.01"/>
        </geometry>
        <!--<pose frame=''>0 0 0.001 0 -0 0</pose>-->
        <!--<origin xyz="0 0 0.001" rpy="0 -0 0" />-->


        <!--<transparency>0</transparency>
        <cast_shadows>1</cast_shadows>
        <material name="tracks_mat">
          <shader type='pixel'>
            <normal_map>__default__</normal_map>
          </shader>
          <script>
            <name>ModelPreview_1::anki_vector::anki_vector::robot::tracks::visual_MATERIAL_</name>
          </script>
          <ambient>0 0 0 1</ambient>
          <diffuse>0 0 0 1</diffuse>
          <specular>0 0 0 1</specular>
          <emissive>0 0 0 1</emissive>
        </material>-->
      </visual>
      <collision name='collision'>
        <laser_retro>0</laser_retro>
        <max_contacts>10</max_contacts>
        <!--<pose frame=''>-0.019 0 0 0 -0 0</pose>-->
        <origin xyz="-0.019 0 0.1" rpy="0 -0 0" />
        <geometry>
          <box size="0.072 0.055 0.06"/>
        </geometry>
      </collision>
    </link>
    <link name='anki_vector::anki_vector::robot::wheel_BL'>
      <!--<pose frame=''>-0.045 0.022 0.0105 0 -0 0</pose>-->
      <!--<origin xyz="-0.045 0.022 0.0105" rpy="0 -0 0" />-->
      <inertial>
        <mass value="0.2"/>
        <inertia ixx="0.001" ixy="0.0" ixz="0.0" iyy="0.001" iyz="0.0" izz="0.001"/>
        <pose frame=''>0 0 0 0 -0 0</pose>
        <origin xyz="0 0 0" rpy="0 -0 0" />
      </inertial>
      <visual name='visual'>
        <geometry>
          <mesh filename="wheel_BL.obj" scale="0.01 0.01 0.01"/>
        </geometry>
        <!--<pose frame=''>0.045 -0.022 -0.0105 0 -0 0</pose>-->
        <origin xyz="0.045 -0.022 -0.0105" rpy="0 -0 0" />

        <!--<transparency>0</transparency>
        <cast_shadows>1</cast_shadows>
        <material name="wheel_BL_mat">
          <shader type='pixel'>
            <normal_map>__default__</normal_map>
          </shader>
        </material>-->
      </visual>
      <collision name='collision'>
        <laser_retro>0</laser_retro>
        <max_contacts>10</max_contacts>
        <!--<pose frame=''>0 0 0 -0 1.5707 1.5707</pose>-->
        <origin xyz="0 0 0" rpy="-0 1.5707 1.5707" />
        <geometry>
          <cylinder radius="0.009" length="0.0125" />
        </geometry>
      </collision>
    </link>
    <link name='anki_vector::anki_vector::robot::wheel_BR'>
      <!--<pose frame=''>-0.045 -0.022 0.0105 0 -0 0</pose>-->
      <!--<origin xyz="-0.045 -0.022 0.0105" rpy="0 -0 0" />-->
      <inertial>
        <mass value="0.2"/>
        <inertia ixx="0.001" ixy="0.0" ixz="0.0" iyy="0.001" iyz="0.0" izz="0.001"/>
        <pose frame=''>0 0 0 0 -0 0</pose>
        <!--<origin xyz="0 0 0" rpy="0 -0 0" />-->
      </inertial>
      <self_collide>0</self_collide>
      <enable_wind>0</enable_wind>
      <kinematic>0</kinematic>
      <gravity>1</gravity>
      <visual name='visual'>
        <geometry>
          <mesh filename="wheel_BR.obj" scale="0.01 0.01 0.01"/>
        </geometry>
        <!--<pose frame=''>0.045 0.022 -0.0105 0 -0 0</pose>-->
        <origin xyz="0.045 0.022 -0.0105" rpy="0 -0 0" />
        <transparency>0</transparency>
        <cast_shadows>1</cast_shadows>
        <!--<material>
          <shader type='pixel'>
            <normal_map>__default__</normal_map>
          </shader>
        </material>-->
      </visual>
      <collision name='collision'>
        <laser_retro>0</laser_retro>
        <max_contacts>10</max_contacts>
        <!--<pose frame=''>0 0 0 -0 1.5707 1.5707</pose>-->
        <origin xyz="0 0 0" rpy="-0 1.5707 1.5707" />
        <geometry>
          <cylinder radius="0.009" length="0.0125" />
        </geometry>
      </collision>
    </link>
    <link name='anki_vector::anki_vector::robot::wheel_FL'>
      <!--<pose frame=''>0.003 0.022 0.014 0 -0 0</pose>-->
      <origin xyz="0.003 0.022 0.014" rpy="0 -0 0" />
      <inertial>
        <mass value="0.2"/>
        <inertia ixx="0.001" ixy="0.0" ixz="0.0" iyy="0.001" iyz="0.0" izz="0.001"/>
        <pose frame=''>0 0 0 0 -0 0</pose>
        <origin xyz="0 0 0" rpy="0 -0 0" />
      </inertial>
      <self_collide>0</self_collide>
      <enable_wind>0</enable_wind>
      <kinematic>0</kinematic>
      <gravity>1</gravity>
      <visual name='visual'>
        <geometry>
          <mesh filename="wheel_FL.obj" scale="0.01 0.01 0.01"/>
        </geometry>
        <!--<pose frame=''>-0.003 -0.022 -0.014 0 -0 0</pose>-->
        <origin xyz="0.003 -0.022 -0.014" rpy="0 -0 0" />
        <transparency>0</transparency>
        <cast_shadows>1</cast_shadows>
        <!--<material>
          <shader type='pixel'>
            <normal_map>__default__</normal_map>
          </shader>
        </material>-->
      </visual>
      <collision name='collision'>
        <laser_retro>0</laser_retro>
        <max_contacts>10</max_contacts>
        <!--<pose frame=''>0 0 0 -0 1.5707 1.5707</pose>-->
        <origin xyz="0 0 0" rpy="-0 1.5707 1.5707" />
        <geometry>
          <cylinder radius="0.013" length="0.0125" />
        </geometry>
        <surface>
          <friction>
            <ode>
              <mu>1</mu>
              <mu2>1</mu2>
              <fdir1>0 0 0</fdir1>
              <slip1>0</slip1>
              <slip2>0</slip2>
            </ode>
            <torsional>
              <coefficient>1</coefficient>
              <patch_radius>0</patch_radius>
              <surface_radius>0</surface_radius>
              <use_patch_radius>1</use_patch_radius>
              <ode>
                <slip>0</slip>
              </ode>
            </torsional>
          </friction>
          <bounce>
            <restitution_coefficient>0</restitution_coefficient>
            <threshold>1e+06</threshold>
          </bounce>
          <contact>
            <collide_without_contact>0</collide_without_contact>
            <collide_without_contact_bitmask>1</collide_without_contact_bitmask>
            <collide_bitmask>1</collide_bitmask>
            <ode>
              <soft_cfm>0</soft_cfm>
              <soft_erp>0.2</soft_erp>
              <kp>1e+13</kp>
              <kd>1</kd>
              <max_vel>0.01</max_vel>
              <min_depth>0</min_depth>
            </ode>
            <bullet>
              <split_impulse>1</split_impulse>
              <split_impulse_penetration_threshold>-0.01</split_impulse_penetration_threshold>
              <soft_cfm>0</soft_cfm>
              <soft_erp>0.2</soft_erp>
              <kp>1e+13</kp>
              <kd>1</kd>
            </bullet>
          </contact>
        </surface>
      </collision>
    </link>
    <link name='anki_vector::anki_vector::robot::wheel_FR'>
      <!--<pose frame=''>0.003 -0.022 0.014 0 -0 0</pose>-->
      <!--<origin xyz="0.003 -0.022 0.014" rpy="0 -0 0" />-->
      <inertial>
        <mass value="0.2"/>
        <inertia ixx="0.001" ixy="0.0" ixz="0.0" iyy="0.001" iyz="0.0" izz="0.001"/>
        <pose frame=''>0 0 0 0 -0 0</pose>
        <origin xyz="0 0 0" rpy="0 -0 0" />
      </inertial>
      <self_collide>0</self_collide>
      <enable_wind>0</enable_wind>
      <kinematic>0</kinematic>
      <gravity>1</gravity>
      <visual name='visual'>
        <geometry>
          <mesh filename="wheel_FR.obj" scale="0.01 0.01 0.01"/>
        </geometry>
        <!--<pose frame=''>-0.003 0.022 -0.014 0 -0 0</pose>-->
        <origin xyz="0.003 0.022 -0.014" rpy="0 -0 0" />
        <transparency>0</transparency>
        <cast_shadows>1</cast_shadows>
        <!--<material>
          <shader type='pixel'>
            <normal_map>__default__</normal_map>
          </shader>
        </material>-->
      </visual>
      <collision name='collision'>
        <laser_retro>0</laser_retro>
        <max_contacts>10</max_contacts>
        <!--<pose frame=''>0 0 0 -0 1.5707 1.5707</pose>-->
        <origin xyz="0 0 0" rpy="-0 1.5707 1.5707" />
        <geometry>
          <cylinder radius="0.013" length="0.0125" />
        </geometry>
        <surface>
          <friction>
            <ode>
              <mu>1</mu>
              <mu2>1</mu2>
              <fdir1>0 0 0</fdir1>
              <slip1>0</slip1>
              <slip2>0</slip2>
            </ode>
            <torsional>
              <coefficient>1</coefficient>
              <patch_radius>0</patch_radius>
              <surface_radius>0</surface_radius>
              <use_patch_radius>1</use_patch_radius>
              <ode>
                <slip>0</slip>
              </ode>
            </torsional>
          </friction>
          <bounce>
            <restitution_coefficient>0</restitution_coefficient>
            <threshold>1e+06</threshold>
          </bounce>
          <contact>
            <collide_without_contact>0</collide_without_contact>
            <collide_without_contact_bitmask>1</collide_without_contact_bitmask>
            <collide_bitmask>1</collide_bitmask>
            <ode>
              <soft_cfm>0</soft_cfm>
              <soft_erp>0.2</soft_erp>
              <kp>1e+13</kp>
              <kd>1</kd>
              <max_vel>0.01</max_vel>
              <min_depth>0</min_depth>
            </ode>
            <bullet>
              <split_impulse>1</split_impulse>
              <split_impulse_penetration_threshold>-0.01</split_impulse_penetration_threshold>
              <soft_cfm>0</soft_cfm>
              <soft_erp>0.2</soft_erp>
              <kp>1e+13</kp>
              <kd>1</kd>
            </bullet>
          </contact>
        </surface>
      </collision>
    </link>



    <joint name='anki_vector::anki_vector::robot::forklift' type='fixed'>
      <parent link="body"/>
      <child link="anki_vector::anki_vector::robot::forklift"/>
      <pose frame=''>0 0 0 0 -0 0</pose>
      <!--<origin xyz="0 0 0" rpy="0 -0 0" />-->
      <physics>
        <ode>
          <limit>
            <cfm>0</cfm>
            <erp>0.2</erp>
          </limit>
          <suspension>
            <cfm>0</cfm>
            <erp>0.2</erp>
          </suspension>
        </ode>
      </physics>
    </joint>
    <joint name='anki_vector::anki_vector::robot::head_tilt' type='fixed'>
      <parent link="body"/>
      <child link="anki_vector::anki_vector::robot::head"/>
      <pose frame=''>-0 0 0 0 -0 0</pose>
      <!--<origin xyz="-0 0 0" rpy="0 -0 0" />-->
      <physics>
        <ode>
          <limit>
            <cfm>0</cfm>
            <erp>0.2</erp>
          </limit>
          <suspension>
            <cfm>0</cfm>
            <erp>0.2</erp>
          </suspension>
        </ode>
      </physics>
    </joint>
    <joint name='anki_vector::anki_vector::robot::tracks' type='fixed'>
      <parent link="body"/>
      <child link="anki_vector::anki_vector::robot::tracks"/>
      <pose frame=''>0 0 0 0 -0 0</pose>
      <!--<origin xyz="0 0 0" rpy="0 -0 0" />-->
      <physics>
        <ode>
          <limit>
            <cfm>0</cfm>
            <erp>0.2</erp>
          </limit>
          <suspension>
            <cfm>0</cfm>
            <erp>0.2</erp>
          </suspension>
        </ode>
      </physics>
    </joint>
    <joint name='anki_vector::anki_vector::robot::wheel_BL_hinge' type='revolute'>
      <parent link="body"/>
      <child link="anki_vector::anki_vector::robot::wheel_BL"/>

      <pose frame=''>0 -0 0 0 -0 0</pose>
      <!--<origin xyz="0 0 0" rpy="0 -0 0" />-->
      <!--<origin xyz="0.045 -0.022 -0.0105" rpy="0 -0 0" />-->
      <origin xyz="-0.045 0.022 0.0105" rpy="0 -0 0" />
      <limit lower="-1e+16" upper="1e+16" effort="-1" velocity="-1"/>
      <axis xyz="0 1 0">
        <xyz>0 1 0</xyz>
        <use_parent_model_frame>0</use_parent_model_frame>

        <dynamics>
          <spring_reference>0</spring_reference>
          <spring_stiffness>0</spring_stiffness>
          <damping>0</damping>
          <friction>0</friction>
        </dynamics>
      </axis>
      <physics>
        <ode>
          <limit>
            <cfm>0</cfm>
            <erp>0.2</erp>
          </limit>
          <suspension>
            <cfm>0</cfm>
            <erp>0.2</erp>
          </suspension>
        </ode>
      </physics>
    </joint>
    <joint name='anki_vector::anki_vector::robot::wheel_BR_hinge' type='revolute'>
      <parent link="body"/>
      <child link="anki_vector::anki_vector::robot::wheel_BR"/>
      <pose frame=''>0 0 0 0 -0 0</pose>
      <!--<origin xyz="0 0 0" rpy="0 -0 0" />-->
      <origin xyz="-0.045 -0.022 0.0105" rpy="0 -0 0" />


      <limit lower="-1e+16" upper="1e+16" effort="-1" velocity="-1"/>
      <axis xyz="0 1 0">
        <xyz>0 1 0</xyz>
        <use_parent_model_frame>0</use_parent_model_frame>
        <dynamics>
          <spring_reference>0</spring_reference>
          <spring_stiffness>0</spring_stiffness>
          <damping>0</damping>
          <friction>0</friction>
        </dynamics>
      </axis>
      <physics>
        <ode>
          <limit>
            <cfm>0</cfm>
            <erp>0.2</erp>
          </limit>
          <suspension>
            <cfm>0</cfm>
            <erp>0.2</erp>
          </suspension>
        </ode>
      </physics>
    </joint>
    <joint name='anki_vector::anki_vector::robot::wheel_FL_hinge' type='revolute'>
      <parent link="body"/>
      <child link="anki_vector::anki_vector::robot::wheel_FL"/>
      <limit lower="-1e+16" upper="1e+16" effort="-1" velocity="-1"/>
      <pose frame=''>0 0 0 0 -0 0</pose>
      <!--<origin xyz="0 0 0" rpy="0 -0 0" />-->
      <origin xyz="-0.003 0.022 0.014" rpy="0 -0 0" />

      <axis xyz="0 1 0">
        <xyz>0 1 0</xyz>
        <use_parent_model_frame>0</use_parent_model_frame>
        <dynamics>
          <spring_reference>0</spring_reference>
          <spring_stiffness>0</spring_stiffness>
          <damping>0</damping>
          <friction>0</friction>
        </dynamics>
      </axis>
      <physics>
        <ode>
          <limit>
            <cfm>0</cfm>
            <erp>0.2</erp>
          </limit>
          <suspension>
            <cfm>0</cfm>
            <erp>0.2</erp>
          </suspension>
        </ode>
      </physics>
    </joint>
    <joint name='anki_vector::anki_vector::robot::wheel_FR_hinge' type='revolute'>
      <parent link="body"/>
      <child link="anki_vector::anki_vector::robot::wheel_FR"/>
      <limit lower="-1e+16" upper="1e+16" effort="-1" velocity="-1"/>
      <pose frame=''>0 0 0 0 -0 0</pose>
      <!--<origin xyz="0 0 0" rpy="0 -0 0" />-->
      <origin xyz="-0.003 -0.022 0.014" rpy="0 -0 0" />
      <axis xyz="0 1 0">
        <xyz>0 1 0</xyz>
        <use_parent_model_frame>0</use_parent_model_frame>

        <dynamics>
          <spring_reference>0</spring_reference>
          <spring_stiffness>0</spring_stiffness>
          <damping>0</damping>
          <friction>0</friction>
        </dynamics>
      </axis>
      <physics>
        <ode>
          <limit>
            <cfm>0</cfm>
            <erp>0.2</erp>
          </limit>
          <suspension>
            <cfm>0</cfm>
            <erp>0.2</erp>
          </suspension>
        </ode>
      </physics>
    </joint>

</robot>
